{"asctime": "2025-10-05 13:28:47,607", "name": "asyncio", "levelname": "ERROR", "message": "Exception in callback _ProactorBasePipeTransport._call_connection_lost()\nhandle: <Handle _ProactorBasePipeTransport._call_connection_lost()>", "exc_info": "Traceback (most recent call last):\n  File \"C:\\Program Files\\Python313\\Lib\\asyncio\\events.py\", line 89, in _run\n    self._context.run(self._callback, *self._args)\n    ~~~~~~~~~~~~~~~~~^^^^^^^^^^^^^^^^^^^^^^^^^^^^^\n  File \"C:\\Program Files\\Python313\\Lib\\asyncio\\proactor_events.py\", line 165, in _call_connection_lost\n    self._sock.shutdown(socket.SHUT_RDWR)\n    ~~~~~~~~~~~~~~~~~~~^^^^^^^^^^^^^^^^^^\nConnectionResetError: [WinError 10054] An existing connection was forcibly closed by the remote host"}
{"asctime": "2025-10-05 21:27:04,687", "name": "asyncio", "levelname": "ERROR", "message": "Exception in callback _ProactorBasePipeTransport._call_connection_lost()\nhandle: <Handle _ProactorBasePipeTransport._call_connection_lost()>", "exc_info": "Traceback (most recent call last):\n  File \"C:\\Program Files\\Python313\\Lib\\asyncio\\events.py\", line 89, in _run\n    self._context.run(self._callback, *self._args)\n    ~~~~~~~~~~~~~~~~~^^^^^^^^^^^^^^^^^^^^^^^^^^^^^\n  File \"C:\\Program Files\\Python313\\Lib\\asyncio\\proactor_events.py\", line 165, in _call_connection_lost\n    self._sock.shutdown(socket.SHUT_RDWR)\n    ~~~~~~~~~~~~~~~~~~~^^^^^^^^^^^^^^^^^^\nConnectionResetError: [WinError 10054] An existing connection was forcibly closed by the remote host"}
